Workbook

Sheet Dashboard
A1: Execution Dashboard
A2: Live from the Test Cases tab. Nothing here is typed by hand.
A4: OVERALL | D4: BY CATEGORY
A5: Total cases | B5: =COUNTA('Test Cases'!$A$5:$A$130) -> 126 | D5: Category | E5: Total | F5: Pass | G5: Fail | H5: Blocked | I5: Not Run
A6: Pass | B6: =COUNTIF('Test Cases'!$H$5:$H$130,"Pass") -> 0 | D6: Smoke | E6: =COUNTIF('Test Cases'!$B$5:$B$130,$D6) -> 5 | F6: =COUNTIFS('Test Cases'!$B$5:$B$130,$D6,'Test Cases'!$H$5:$H$130,"Pass") -> 0 | G6: =COUNTIFS('Test Cases'!$B$5:$B$130,$D6,'Test Cases'!$H$5:$H$130,"Fail") -> 0 | H6: =COUNTIFS('Test Cases'!$B$5:$B$130,$D6,'Test Cases'!$H$5:$H$130,"Blocked") -> 0 | I6: =COUNTIFS('Test Cases'!$B$5:$B$130,$D6,'Test Cases'!$H$5:$H$130,"Not Run") -> 5
A7: Fail | B7: =COUNTIF('Test Cases'!$H$5:$H$130,"Fail") -> 0 | D7: Functional | E7: =COUNTIF('Test Cases'!$B$5:$B$130,$D7) -> 28 | F7: =COUNTIFS('Test Cases'!$B$5:$B$130,$D7,'Test Cases'!$H$5:$H$130,"Pass") -> 0 | G7: =COUNTIFS('Test Cases'!$B$5:$B$130,$D7,'Test Cases'!$H$5:$H$130,"Fail") -> 0 | H7: =COUNTIFS('Test Cases'!$B$5:$B$130,$D7,'Test Cases'!$H$5:$H$130,"Blocked") -> 0 | I7: =COUNTIFS('Test Cases'!$B$5:$B$130,$D7,'Test Cases'!$H$5:$H$130,"Not Run") -> 28
A8: Blocked | B8: =COUNTIF('Test Cases'!$H$5:$H$130,"Blocked") -> 0 | D8: End-to-end journeys | E8: =COUNTIF('Test Cases'!$B$5:$B$130,$D8) -> 10 | F8: =COUNTIFS('Test Cases'!$B$5:$B$130,$D8,'Test Cases'!$H$5:$H$130,"Pass") -> 0 | G8: =COUNTIFS('Test Cases'!$B$5:$B$130,$D8,'Test Cases'!$H$5:$H$130,"Fail") -> 0 | H8: =COUNTIFS('Test Cases'!$B$5:$B$130,$D8,'Test Cases'!$H$5:$H$130,"Blocked") -> 0 | I8: =COUNTIFS('Test Cases'!$B$5:$B$130,$D8,'Test Cases'!$H$5:$H$130,"Not Run") -> 10
A9: N/A | B9: =COUNTIF('Test Cases'!$H$5:$H$130,"N/A") -> 0 | D9: Integration | E9: =COUNTIF('Test Cases'!$B$5:$B$130,$D9) -> 8 | F9: =COUNTIFS('Test Cases'!$B$5:$B$130,$D9,'Test Cases'!$H$5:$H$130,"Pass") -> 0 | G9: =COUNTIFS('Test Cases'!$B$5:$B$130,$D9,'Test Cases'!$H$5:$H$130,"Fail") -> 0 | H9: =COUNTIFS('Test Cases'!$B$5:$B$130,$D9,'Test Cases'!$H$5:$H$130,"Blocked") -> 0 | I9: =COUNTIFS('Test Cases'!$B$5:$B$130,$D9,'Test Cases'!$H$5:$H$130,"Not Run") -> 8
A10: Not Run | B10: =COUNTIF('Test Cases'!$H$5:$H$130,"Not Run") -> 126 | D10: Security | E10: =COUNTIF('Test Cases'!$B$5:$B$130,$D10) -> 16 | F10: =COUNTIFS('Test Cases'!$B$5:$B$130,$D10,'Test Cases'!$H$5:$H$130,"Pass") -> 0 | G10: =COUNTIFS('Test Cases'!$B$5:$B$130,$D10,'Test Cases'!$H$5:$H$130,"Fail") -> 0 | H10: =COUNTIFS('Test Cases'!$B$5:$B$130,$D10,'Test Cases'!$H$5:$H$130,"Blocked") -> 0 | I10: =COUNTIFS('Test Cases'!$B$5:$B$130,$D10,'Test Cases'!$H$5:$H$130,"Not Run") -> 16
A11: Executed | B11: =B5-B10 -> 0 | D11: Resilience | E11: =COUNTIF('Test Cases'!$B$5:$B$130,$D11) -> 9 | F11: =COUNTIFS('Test Cases'!$B$5:$B$130,$D11,'Test Cases'!$H$5:$H$130,"Pass") -> 0 | G11: =COUNTIFS('Test Cases'!$B$5:$B$130,$D11,'Test Cases'!$H$5:$H$130,"Fail") -> 0 | H11: =COUNTIFS('Test Cases'!$B$5:$B$130,$D11,'Test Cases'!$H$5:$H$130,"Blocked") -> 0 | I11: =COUNTIFS('Test Cases'!$B$5:$B$130,$D11,'Test Cases'!$H$5:$H$130,"Not Run") -> 9
A12: Pass rate (of executed) | B12: =IFERROR(B6/(B6+B7+B8),0) -> 0 | D12: Data correctness | E12: =COUNTIF('Test Cases'!$B$5:$B$130,$D12) -> 9 | F12: =COUNTIFS('Test Cases'!$B$5:$B$130,$D12,'Test Cases'!$H$5:$H$130,"Pass") -> 0 | G12: =COUNTIFS('Test Cases'!$B$5:$B$130,$D12,'Test Cases'!$H$5:$H$130,"Fail") -> 0 | H12: =COUNTIFS('Test Cases'!$B$5:$B$130,$D12,'Test Cases'!$H$5:$H$130,"Blocked") -> 0 | I12: =COUNTIFS('Test Cases'!$B$5:$B$130,$D12,'Test Cases'!$H$5:$H$130,"Not Run") -> 9
D13: Privacy and retention | E13: =COUNTIF('Test Cases'!$B$5:$B$130,$D13) -> 8 | F13: =COUNTIFS('Test Cases'!$B$5:$B$130,$D13,'Test Cases'!$H$5:$H$130,"Pass") -> 0 | G13: =COUNTIFS('Test Cases'!$B$5:$B$130,$D13,'Test Cases'!$H$5:$H$130,"Fail") -> 0 | H13: =COUNTIFS('Test Cases'!$B$5:$B$130,$D13,'Test Cases'!$H$5:$H$130,"Blocked") -> 0 | I13: =COUNTIFS('Test Cases'!$B$5:$B$130,$D13,'Test Cases'!$H$5:$H$130,"Not Run") -> 8
D14: Performance and concurrency | E14: =COUNTIF('Test Cases'!$B$5:$B$130,$D14) -> 6 | F14: =COUNTIFS('Test Cases'!$B$5:$B$130,$D14,'Test Cases'!$H$5:$H$130,"Pass") -> 0 | G14: =COUNTIFS('Test Cases'!$B$5:$B$130,$D14,'Test Cases'!$H$5:$H$130,"Fail") -> 0 | H14: =COUNTIFS('Test Cases'!$B$5:$B$130,$D14,'Test Cases'!$H$5:$H$130,"Blocked") -> 0 | I14: =COUNTIFS('Test Cases'!$B$5:$B$130,$D14,'Test Cases'!$H$5:$H$130,"Not Run") -> 6
D15: Usability and call quality | E15: =COUNTIF('Test Cases'!$B$5:$B$130,$D15) -> 8 | F15: =COUNTIFS('Test Cases'!$B$5:$B$130,$D15,'Test Cases'!$H$5:$H$130,"Pass") -> 0 | G15: =COUNTIFS('Test Cases'!$B$5:$B$130,$D15,'Test Cases'!$H$5:$H$130,"Fail") -> 0 | H15: =COUNTIFS('Test Cases'!$B$5:$B$130,$D15,'Test Cases'!$H$5:$H$130,"Blocked") -> 0 | I15: =COUNTIFS('Test Cases'!$B$5:$B$130,$D15,'Test Cases'!$H$5:$H$130,"Not Run") -> 8
D16: Compatibility | E16: =COUNTIF('Test Cases'!$B$5:$B$130,$D16) -> 7 | F16: =COUNTIFS('Test Cases'!$B$5:$B$130,$D16,'Test Cases'!$H$5:$H$130,"Pass") -> 0 | G16: =COUNTIFS('Test Cases'!$B$5:$B$130,$D16,'Test Cases'!$H$5:$H$130,"Fail") -> 0 | H16: =COUNTIFS('Test Cases'!$B$5:$B$130,$D16,'Test Cases'!$H$5:$H$130,"Blocked") -> 0 | I16: =COUNTIFS('Test Cases'!$B$5:$B$130,$D16,'Test Cases'!$H$5:$H$130,"Not Run") -> 7
D17: Regression set | E17: =COUNTIF('Test Cases'!$B$5:$B$130,$D17) -> 7 | F17: =COUNTIFS('Test Cases'!$B$5:$B$130,$D17,'Test Cases'!$H$5:$H$130,"Pass") -> 0 | G17: =COUNTIFS('Test Cases'!$B$5:$B$130,$D17,'Test Cases'!$H$5:$H$130,"Fail") -> 0 | H17: =COUNTIFS('Test Cases'!$B$5:$B$130,$D17,'Test Cases'!$H$5:$H$130,"Blocked") -> 0 | I17: =COUNTIFS('Test Cases'!$B$5:$B$130,$D17,'Test Cases'!$H$5:$H$130,"Not Run") -> 7
D18: Deployment | E18: =COUNTIF('Test Cases'!$B$5:$B$130,$D18) -> 5 | F18: =COUNTIFS('Test Cases'!$B$5:$B$130,$D18,'Test Cases'!$H$5:$H$130,"Pass") -> 0 | G18: =COUNTIFS('Test Cases'!$B$5:$B$130,$D18,'Test Cases'!$H$5:$H$130,"Fail") -> 0 | H18: =COUNTIFS('Test Cases'!$B$5:$B$130,$D18,'Test Cases'!$H$5:$H$130,"Blocked") -> 0 | I18: =COUNTIFS('Test Cases'!$B$5:$B$130,$D18,'Test Cases'!$H$5:$H$130,"Not Run") -> 5
D21: KNOWN DEFECTS — expected to fail
E22: Total | F22: Confirmed (Fail) | G22: Now passing | H22: Not Run
D23: Audit regressions | E23: =COUNTIF('Test Cases'!$G$5:$G$130,"KNOWN DEFECT") -> 8 | F23: =COUNTIFS('Test Cases'!$G$5:$G$130,"KNOWN DEFECT",'Test Cases'!$H$5:$H$130,"Fail") -> 0 | G23: =COUNTIFS('Test Cases'!$G$5:$G$130,"KNOWN DEFECT",'Test Cases'!$H$5:$H$130,"Pass") -> 0 | H23: =COUNTIFS('Test Cases'!$G$5:$G$130,"KNOWN DEFECT",'Test Cases'!$H$5:$H$130,"Not Run") -> 8
D25: A 'Fail' on these eight confirms a defect the remediation audit already identified — that is the intended result. A 'Pass' means it has been fixed since; note which one and tell the team.

Sheet Instructions
A1: Voice Agent v3.0.0 — Test Execution Workbook
A2: 126 test cases for end-to-end verification. Built against the codebase as at 16 September 2026.
A5: HOW TO USE THIS WORKBOOK
A7: 1. | B7: Work through the 'Setup Checklist' tab first. Nothing else will give trustworthy results until every item there is done.
A8: 2. | B8: Run cases from the 'Test Cases' tab. Fill in ONLY the yellow columns — Status, Actual Result, Evidence, Tester, Date Run, Defect ID.
A9: 3. | B9: Every column left of Status is reference material. Do not edit it: the Dashboard counts depend on those values.
A10: 4. | B10: When a case fails, log it on the 'Defect Log' tab and put the defect ID back on the test row so the two link up.
A11: 5. | B11: The 'Dashboard' tab updates itself. Do not type into it.
A13: STATUS VALUES | B13: Pick from the dropdown in column H. These five are what the Dashboard counts.
A15: Not Run | B15: Not attempted yet. Every case starts here.
A16: Pass | B16: Behaved exactly as the Expected Result column describes.
A17: Fail | B17: Did not. Log a defect and reference it in column M.
A18: Blocked | B18: Could not be run — missing access, environment down, or a dependency failed. Say why in Actual Result.
A19: N/A | B19: Not applicable to this build or environment. Say why.
A21: EXPECTED OUTCOME COLUMN
A23: Pass expected | B23: Normal case. A Fail here is a new finding.
A24: KNOWN DEFECT | B24: Eight cases are expected to FAIL. They confirm defects the remediation audit already identified. Mark them Fail and note the evidence — that is the point. A Pass on one of these means the defect has been fixed since the audit, which is also worth recording.
A26: EXAMPLE OF A COMPLETED ROW | B26: How the fillable columns should look once a case has been run.
A28: Status | B28: Actual Result | C28: Evidence / Log Ref | D28: Tester | E28: Date Run | F28: Defect ID
A29: Fail | B29: Agent booked 14:00 but calendar shows 09:30 — shifted by UTC offset | C29: run-2026-09-17.log line 4412 | D29: Abhigna | E29: 2026-09-17 | F29: VA-T-003

Sheet Setup Checklist
A1: Setup Checklist
A2: Complete every item before running any test case. Column C is yours to fill in.
A4: Area | B4: Item | C4: Done | D4: Notes
A5: Credentials | B5: Twilio number provisioned, with TWILIO_ACCOUNT_SID / TWILIO_AUTH_TOKEN / TWILIO_PHONE_NUMBER in .env
A6: Credentials | B6: OPENAI_API_KEY set
A7: Credentials | B7: ELEVENLABS_API_KEY set — speech-to-text has NO fallback provider, calls fail to transcribe without it
A8: Credentials | B8: SARVAM_API_KEY set (default/fallback voice)
A9: Credentials | B9: DASHBOARD_API_KEY generated and set — blank means every API call is refused
A10: Credentials | B10: DASHBOARD_ADMIN_KEY generated and set — same, plus the dashboard proxy needs it
A11: Credentials | B11: DATABASE_URL points at a Postgres with the pgvector extension available
A12: Environment | B12: backend: pip install -r requirements.txt -r requirements-dev.txt
A13: Environment | B13: frontend: npm install
A14: Environment | B14: frontend/.env populated — BACKEND_INTERNAL_URL and DASHBOARD_ADMIN_KEY
A15: Environment | B15: Schema created: alembic upgrade head
A16: Environment | B16: Default settings seeded: python scripts/setup_db.py
... A34: Access | B34: Kubernetes access, or a named owner for the Deployment cases if not

Sheet Test Cases
A1: Test Cases
A2: Reference columns A-G are fixed. Fill in the shaded columns H-M only.
A4: Test ID | B4: Category | C4: Test Case | D4: Steps | E4: Expected Result | F4: Relates To | G4: Expected Outcome | H4: Status | I4: Actual Result | J4: Evidence / Log Ref | K4: Tester | L4: Date Run | M4: Defect ID
A5: SMK-01 | B5: Smoke | C5: Backend starts and answers | D5: 1. Start the backend. 2. curl localhost:8000/health | E5: 200, JSON showing status ok plus the agent name, company name and version from your config. | G5: Pass expected | H5: Not Run
A6: SMK-02 | B6: Smoke | C6: Readiness reports the database | D6: 1. curl -i localhost:8000/ready | E6: 200 with database_connected: true. Redis may be false without failing the probe — that is correct. | F6: VA-C4 | G6: Pass expected | H6: Not Run
A7: SMK-03 | B7: Smoke | C7: All eight dashboard pages load | D7: 1. Open each: dashboard, calls, leads, meetings, escalations, documents, analytics, settings. | E7: Every page renders with no console error and no infinite spinner. Empty tables are fine on a fresh database. | G7: Pass expected | H7: Not Run
A8: SMK-04 | B8: Smoke | C8: A call connects and the agent speaks | D8: 1. Dial the Twilio number. 2. Wait for the greeting. | E8: Greeting plays within a couple of seconds and matches GREETING_TEMPLATE with your agent and company names filled in. No dead air. | G8: Pass expected | H8: Not Run
A9: SMK-05 | B9: Smoke | C9: The call reaches the dashboard | D9: 1. Hang up from SMK-04. 2. Open the calls page. | E9: A new row with a masked phone number, a duration, and a transcript you can open. | G9: Pass expected | H9: Not Run
A10: FUNC-01 | B10: Functional | C10: Greeting matches configuration | D10: 1. Read GREETING_TEMPLATE, AGENT_NAME, COMPANY_NAME from config. 2. Call and listen. | E10: Spoken greeting matches the template exactly with names substituted. It must not offer Tamil or Hindi — this is an English-only build. | F10: VA-D2 | G10: Pass expected | H10: Not Run
A11: FUNC-02 | B11: Functional | C11: A knowledge-base question is answered correctly | D11: 1. Ask a question your prepared document answers. | E11: The answer contains the fact from your document. It should not mention the knowledge base, a heading, or that context was provided. | G11: Pass expected | H11: Not Run
A12: FUNC-03 | B12: Functional | C12: An unanswerable question is refused honestly | D12: 1. Ask about something plainly not in the knowledge base ("do you sell bicycles?"). | E12: The agent says it does not have that information. It must not invent an answer from a loosely related chunk. | G12: Pass expected | H12: Not Run
A13: FUNC-04 | B13: Functional | C13: Routing: factual question goes to knowledge | D13: 1. Ask about services or pricing. 2. Check the log for the chosen route. | E13: Route is knowledge. | G13: Pass expected | H13: Not Run
A14: FUNC-05 | B14: Functional | C14: Routing: booking request goes to action | D14: 1. Say "I'd like to book a meeting". 2. Check the log. | E14: Route is action. | G14: Pass expected | H14: Not Run
A15: FUNC-06 | B15: Functional | C15: Routing: asking for a human goes to escalation | D15: 1. Say "I want to speak to a real person". 2. Check the log. | E15: Route is escalation and an escalation record is created. | G15: Pass expected | H15: Not Run
A16: FUNC-07 | B16: Functional | C16: Routing: pure small talk goes direct | D16: 1. Say only "thanks, bye". 2. Check the log. | E16: Route is direct — no knowledge search and no specialist call. This is a cost test as much as a behaviour test. | G16: Pass expected | H16: Not Run
A17: FUNC-08 | B17: Functional | C17: Sticky routing keeps a flow together | D17: 1. Start a booking. 2. Answer a follow-up with something short like "Tuesday". | E17: The short reply goes straight back to the action agent without re-running the router. Sticky route lasts 120 seconds by default. | G17: Pass expected | H17: Not Run
A18: FUNC-09 | B18: Functional | C18: An acknowledgement does not hijack a flow | D18: 1. Mid-booking, say only "okay buddy". | E18: Treated as small talk, not fed into the specialist. Both words are in the acknowledgement list, which is what makes this the interesting case. | G18: Pass expected | H18: Not Run
A19: FUNC-10 | B19: Functional | C19: A lead is saved | D19: 1. Give a name, a phone number and an interest. | E19: Lead appears on the leads page with the phone number masked, linked to this call. | G19: Pass expected | H19: Not Run
A20: FUNC-11 | B20: Functional | C20: A too-short phone number is refused | D20: 1. Deliberately give only 8 digits. | E20: The agent asks you to repeat it. Nothing is saved. The log shows the rejection reason. | G20: Pass expected | H20: Not Run
A21: FUNC-12 | B21: Functional | C21: A number you never said is refused | D21: 1. Give a number, then when the agent reads it back, check the digits. | E21: A number the agent produces that does not appear in what you actually said is rejected. This guard exists because the model has hallucinated digits before. | F21: anti-hallucination | G21: Pass expected | H21: Not Run
A22: FUNC-13 | B22: Functional | C22: Booking details are confirmed before booking | D22: 1. Go through a booking to the point of confirmation. | E22: The agent reads back name, number and time and waits for agreement before creating anything. | G22: Pass expected | H22: Not Run
A23: FUNC-14 | B23: Functional | C23: A valid meeting books | D23: 1. Ask for a time 3 days out at 11:00. | E23: Booking succeeds, appears on the meetings page, and — if Calendar is configured — in the calendar at the time you said, not shifted. | F23: VA-C7 | G23: Pass expected | H23: Not Run
A24: FUNC-15 | B24: Functional | C24: A meeting in the past is refused | D24: 1. Ask for yesterday at 10:00. | E24: Refused with a reason. The agent asks for a future time and does not pick one itself. A booking must not be created. | F24: VA-C7 | G24: Pass expected | H24: Not Run
A25: FUNC-16 | B25: Functional | C25: A meeting too far ahead is refused | D25: 1. Ask for a date more than 60 days out. | E25: Refused, agent asks for something sooner. Bound is MEETING_MAX_DAYS_AHEAD, default 60. | F25: VA-C7 | G25: Pass expected | H25: Not Run
A26: FUNC-17 | B26: Functional | C26: A meeting outside business hours is refused | D26: 1. Ask for 07:00, then separately for 21:00. | E26: Both refused. Window is 09:00–18:00 by default, start inclusive and end exclusive — so 18:00 itself should also be refused. Test that boundary. | F26: VA-C7 | G26: Pass expected | H26: Not Run
A27: FUNC-18 | B27: Functional | C27: An unparseable time does not silently book | D27: 1. Give something the model may mangle — "sometime next quarter-ish". | E27: Either the agent asks for clarification, or the booking is refused. It must never book the current moment instead. This was a real defect. | F27: VA-C7 | G27: Pass expected | H27: Not Run
A28: FUNC-19 | B28: Functional | C28: Escalation is recorded | D28: 1. Express frustration or ask for a human. | E28: Escalation appears on the escalations page with a reason and a transcript snippet. | G28: Pass expected | H28: Not Run
A29: FUNC-20 | B29: Functional | C29: An escalation can be resolved | D29: 1. Click resolve on the escalations page. | E29: Marked resolved, timestamp recorded, and it moves out of the unresolved filter. | G29: Pass expected | H29: Not Run
A30: FUNC-21 | B30: Functional | C30: Filler sounds are ignored | D30: 1. Say only "um", pause, then "hmm". | E30: No turn is triggered, no reply generated, nothing added to the transcript. | G30: Pass expected | H30: Not Run
A31: FUNC-22 | B31: Functional | C31: Short real answers are NOT ignored | D31: 1. Answer a yes/no question with just "yes". Repeat with "no" and "okay". | E31: Each is treated as a real answer. These are deliberately excluded from the filler list — a regression here breaks every confirmation flow. | G31: Pass expected | H31: Not Run
A32: FUNC-23 | B32: Functional | C32: A settings change reaches the next call | D32: 1. Change the agent name on the settings page. 2. Call again. | E32: The new name is spoken in the greeting. The cache is invalidated on save, so no restart should be needed. | G32: Pass expected | H32: Not Run
A33: FUNC-24 | B33: Functional | C33: An uploaded document becomes answerable | D33: 1. Upload your prepared .md on the documents page. 2. Call and ask about a fact only that file contains. | E33: The agent answers using the new content, with no restart. | G33: Pass expected | H33: Not Run
A34: FUNC-25 | B34: Functional | C34: A wrong file type is rejected | D34: 1. Try to upload a .docx or .exe. | E34: Rejected. Only .md, .txt and .pdf are allowed. | G34: Pass expected | H34: Not Run
A35: FUNC-26 | B35: Functional | C35: An oversized file is rejected | D35: 1. Try to upload a file over 10 MB. | E35: Rejected before processing. | G35: Pass expected | H35: Not Run
A36: FUNC-27 | B36: Functional | C36: Deleting a document needs confirmation | D36: 1. curl -X DELETE .../api/documents/yourfile.md -H "Authorization: Bearer $DASHBOARD_ADMIN_KEY" 2. Then repeat with ?confirm=true. | E36: First call 400 and deletes nothing. Second call deletes. | F36: VA-B4 | G36: Pass expected | H36: Not Run
A37: FUNC-28 | B37: Functional | C37: Deleting an unknown document is a clean 404 | D37: 1. Delete a source name that does not exist, with confirm=true. | E37: 404, and no side effects. | F37: VA-B4 | G37: Pass expected | H37: Not Run
A38: E2E-01 | B38: End-to-end journeys | C38: Enquiry call, start to finish | D38: 1. Call, hear the greeting. 2. Ask two related factual questions. 3. Say goodbye and hang up. | E38: Both answered correctly and in context. After hanging up: a call row with correct duration, a full transcript with turns attributed to the right speaker, and a cost figure. | G38: Pass expected | H38: Not Run
A39: E2E-02 | B39: End-to-end journeys | C39: Lead capture, start to finish | D39: 1. Call, express interest in a service. 2. Provide name, phone and interest when asked. 3. Hang up. | E39: Lead on the leads page, correctly linked to this call, phone masked in the UI, and an event on the analytics feed. | G39: Pass expected | H39: Not Run
A40: E2E-03 | B40: End-to-end journeys | C40: Meeting booking, start to finish | D40: 1. Call and ask to book. 2. Give details, confirm when read back. 3. Hang up, then check dashboard and calendar. | E40: Meeting on the meetings page at the time you spoke — not shifted by a timezone offset — with the lead's name attached, and a matching calendar entry. | G40: Pass expected | H40: Not Run
A41: E2E-04 | B41: End-to-end journeys | C41: Escalation, start to finish | D41: 1. Call and ask for a human. 2. Hang up. 3. Resolve the escalation in the dashboard. | E41: Escalation captured with a usable snippet, then resolved and timestamped. | G41: Pass expected | H41: Not Run
...

Sheet Defect Log
A1: Defect Log
A2: One row per defect found. Put the Defect ID back on the failing test row so the two link up.
A4: Defect ID | B4: Test ID | C4: Title | D4: Severity | E4: Steps to Reproduce | F4: Actual vs Expected | G4: Evidence | H4: Raised By | I4: Status
A5: VA-T-001 | B5: FUNC-17 | C5: EXAMPLE — Booking accepted at 18:00, outside business hours | D5: Medium | E5: 1. Call. 2. Ask to book a meeting at 18:00 tomorrow. 3. Confirm when read back. | F5: Expected refusal (window is 09:00-18:00, end exclusive). Actual: booking created and calendar entry made. | G5: run-2026-09-17.log:4412 | H5: Abhigna | I5: Open
